Watching for file changes with StatReloader
Internal Server Error: /dashboard/api/home/configuration/
Traceback (most recent call last):
  File "/home/mz/Code/dashboard/django/venv/lib/python3.11/site-packages/django/db/backends/utils.py", line 89, in _execute
    return self.cursor.execute(sql, params)
           ^^^^^^^^^^^^^^^^^^^^^^^^^^^^^^^^
  File "/home/mz/Code/dashboard/django/venv/lib/python3.11/site-packages/django/db/backends/sqlite3/base.py", line 328, in execute
    return super().execute(query, params)
           ^^^^^^^^^^^^^^^^^^^^^^^^^^^^^^
sqlite3.OperationalError: database is locked

The above exception was the direct cause of the following exception:

Traceback (most recent call last):
  File "/home/mz/Code/dashboard/django/venv/lib/python3.11/site-packages/django/core/handlers/exception.py", line 55, in inner
    response = get_response(request)
               ^^^^^^^^^^^^^^^^^^^^^
  File "/home/mz/Code/dashboard/django/dashboard/middleware.py", line 60, in __call__
    log.save()
  File "/home/mz/Code/dashboard/django/venv/lib/python3.11/site-packages/django/db/models/base.py", line 814, in save
    self.save_base(
  File "/home/mz/Code/dashboard/django/venv/lib/python3.11/site-packages/django/db/models/base.py", line 877, in save_base
    updated = self._save_table(
              ^^^^^^^^^^^^^^^^^
  File "/home/mz/Code/dashboard/django/venv/lib/python3.11/site-packages/django/db/models/base.py", line 1020, in _save_table
    results = self._do_insert(
              ^^^^^^^^^^^^^^^^
  File "/home/mz/Code/dashboard/django/venv/lib/python3.11/site-packages/django/db/models/base.py", line 1061, in _do_insert
    return manager._insert(
           ^^^^^^^^^^^^^^^^
  File "/home/mz/Code/dashboard/django/venv/lib/python3.11/site-packages/django/db/models/manager.py", line 87, in manager_method
    return getattr(self.get_queryset(), name)(*args, **kwargs)
           ^^^^^^^^^^^^^^^^^^^^^^^^^^^^^^^^^^^^^^^^^^^^^^^^^^^
  File "/home/mz/Code/dashboard/django/venv/lib/python3.11/site-packages/django/db/models/query.py", line 1805, in _insert
    return query.get_compiler(using=using).execute_sql(returning_fields)
           ^^^^^^^^^^^^^^^^^^^^^^^^^^^^^^^^^^^^^^^^^^^^^^^^^^^^^^^^^^^^^
  File "/home/mz/Code/dashboard/django/venv/lib/python3.11/site-packages/django/db/models/sql/compiler.py", line 1820, in execute_sql
    cursor.execute(sql, params)
  File "/home/mz/Code/dashboard/django/venv/lib/python3.11/site-packages/django/db/backends/utils.py", line 67, in execute
    return self._execute_with_wrappers(
           ^^^^^^^^^^^^^^^^^^^^^^^^^^^^
  File "/home/mz/Code/dashboard/django/venv/lib/python3.11/site-packages/django/db/backends/utils.py", line 80, in _execute_with_wrappers
    return executor(sql, params, many, context)
           ^^^^^^^^^^^^^^^^^^^^^^^^^^^^^^^^^^^^
  File "/home/mz/Code/dashboard/django/venv/lib/python3.11/site-packages/django/db/backends/utils.py", line 84, in _execute
    with self.db.wrap_database_errors:
  File "/home/mz/Code/dashboard/django/venv/lib/python3.11/site-packages/django/db/utils.py", line 91, in __exit__
    raise dj_exc_value.with_traceback(traceback) from exc_value
  File "/home/mz/Code/dashboard/django/venv/lib/python3.11/site-packages/django/db/backends/utils.py", line 89, in _execute
    return self.cursor.execute(sql, params)
           ^^^^^^^^^^^^^^^^^^^^^^^^^^^^^^^^
  File "/home/mz/Code/dashboard/django/venv/lib/python3.11/site-packages/django/db/backends/sqlite3/base.py", line 328, in execute
    return super().execute(query, params)
           ^^^^^^^^^^^^^^^^^^^^^^^^^^^^^^
django.db.utils.OperationalError: database is locked
Internal Server Error: /dashboard/api/auth/me/
Traceback (most recent call last):
  File "/home/mz/Code/dashboard/django/venv/lib/python3.11/site-packages/django/db/backends/utils.py", line 89, in _execute
    return self.cursor.execute(sql, params)
           ^^^^^^^^^^^^^^^^^^^^^^^^^^^^^^^^
  File "/home/mz/Code/dashboard/django/venv/lib/python3.11/site-packages/django/db/backends/sqlite3/base.py", line 328, in execute
    return super().execute(query, params)
           ^^^^^^^^^^^^^^^^^^^^^^^^^^^^^^
sqlite3.OperationalError: database is locked

The above exception was the direct cause of the following exception:

Traceback (most recent call last):
  File "/home/mz/Code/dashboard/django/venv/lib/python3.11/site-packages/django/core/handlers/exception.py", line 55, in inner
    response = get_response(request)
               ^^^^^^^^^^^^^^^^^^^^^
  File "/home/mz/Code/dashboard/django/dashboard/middleware.py", line 60, in __call__
    log.save()
  File "/home/mz/Code/dashboard/django/venv/lib/python3.11/site-packages/django/db/models/base.py", line 814, in save
    self.save_base(
  File "/home/mz/Code/dashboard/django/venv/lib/python3.11/site-packages/django/db/models/base.py", line 877, in save_base
    updated = self._save_table(
              ^^^^^^^^^^^^^^^^^
  File "/home/mz/Code/dashboard/django/venv/lib/python3.11/site-packages/django/db/models/base.py", line 1020, in _save_table
    results = self._do_insert(
              ^^^^^^^^^^^^^^^^
  File "/home/mz/Code/dashboard/django/venv/lib/python3.11/site-packages/django/db/models/base.py", line 1061, in _do_insert
    return manager._insert(
           ^^^^^^^^^^^^^^^^
  File "/home/mz/Code/dashboard/django/venv/lib/python3.11/site-packages/django/db/models/manager.py", line 87, in manager_method
    return getattr(self.get_queryset(), name)(*args, **kwargs)
           ^^^^^^^^^^^^^^^^^^^^^^^^^^^^^^^^^^^^^^^^^^^^^^^^^^^
  File "/home/mz/Code/dashboard/django/venv/lib/python3.11/site-packages/django/db/models/query.py", line 1805, in _insert
    return query.get_compiler(using=using).execute_sql(returning_fields)
           ^^^^^^^^^^^^^^^^^^^^^^^^^^^^^^^^^^^^^^^^^^^^^^^^^^^^^^^^^^^^^
  File "/home/mz/Code/dashboard/django/venv/lib/python3.11/site-packages/django/db/models/sql/compiler.py", line 1820, in execute_sql
    cursor.execute(sql, params)
  File "/home/mz/Code/dashboard/django/venv/lib/python3.11/site-packages/django/db/backends/utils.py", line 67, in execute
    return self._execute_with_wrappers(
           ^^^^^^^^^^^^^^^^^^^^^^^^^^^^
  File "/home/mz/Code/dashboard/django/venv/lib/python3.11/site-packages/django/db/backends/utils.py", line 80, in _execute_with_wrappers
    return executor(sql, params, many, context)
           ^^^^^^^^^^^^^^^^^^^^^^^^^^^^^^^^^^^^
  File "/home/mz/Code/dashboard/django/venv/lib/python3.11/site-packages/django/db/backends/utils.py", line 84, in _execute
    with self.db.wrap_database_errors:
  File "/home/mz/Code/dashboard/django/venv/lib/python3.11/site-packages/django/db/utils.py", line 91, in __exit__
    raise dj_exc_value.with_traceback(traceback) from exc_value
  File "/home/mz/Code/dashboard/django/venv/lib/python3.11/site-packages/django/db/backends/utils.py", line 89, in _execute
    return self.cursor.execute(sql, params)
           ^^^^^^^^^^^^^^^^^^^^^^^^^^^^^^^^
  File "/home/mz/Code/dashboard/django/venv/lib/python3.11/site-packages/django/db/backends/sqlite3/base.py", line 328, in execute
    return super().execute(query, params)
           ^^^^^^^^^^^^^^^^^^^^^^^^^^^^^^
django.db.utils.OperationalError: database is locked
Watching for file changes with StatReloader
Not Found: /
Not Found: /favicon.ico
Not Found: /
Not Found: /
Not Found: /favicon.ico
Not Found: /
Invalid HTTP_HOST header: '127.0.0.1:8000'. You may need to add '127.0.0.1' to ALLOWED_HOSTS.
Traceback (most recent call last):
  File "/home/mz/Code/dashboard/django/venv/lib/python3.11/site-packages/django/core/handlers/exception.py", line 55, in inner
    response = get_response(request)
               ^^^^^^^^^^^^^^^^^^^^^
  File "/home/mz/Code/dashboard/django/venv/lib/python3.11/site-packages/django/utils/deprecation.py", line 133, in __call__
    response = self.process_request(request)
               ^^^^^^^^^^^^^^^^^^^^^^^^^^^^^
  File "/home/mz/Code/dashboard/django/venv/lib/python3.11/site-packages/django/middleware/common.py", line 48, in process_request
    host = request.get_host()
           ^^^^^^^^^^^^^^^^^^
  File "/home/mz/Code/dashboard/django/venv/lib/python3.11/site-packages/django/http/request.py", line 150, in get_host
    raise DisallowedHost(msg)
django.core.exceptions.DisallowedHost: Invalid HTTP_HOST header: '127.0.0.1:8000'. You may need to add '127.0.0.1' to ALLOWED_HOSTS.
Bad Request: /
Invalid HTTP_HOST header: '127.0.0.1:8000'. You may need to add '127.0.0.1' to ALLOWED_HOSTS.
Traceback (most recent call last):
  File "/home/mz/Code/dashboard/django/venv/lib/python3.11/site-packages/django/core/handlers/exception.py", line 55, in inner
    response = get_response(request)
               ^^^^^^^^^^^^^^^^^^^^^
  File "/home/mz/Code/dashboard/django/venv/lib/python3.11/site-packages/django/utils/deprecation.py", line 133, in __call__
    response = self.process_request(request)
               ^^^^^^^^^^^^^^^^^^^^^^^^^^^^^
  File "/home/mz/Code/dashboard/django/venv/lib/python3.11/site-packages/django/middleware/common.py", line 48, in process_request
    host = request.get_host()
           ^^^^^^^^^^^^^^^^^^
  File "/home/mz/Code/dashboard/django/venv/lib/python3.11/site-packages/django/http/request.py", line 150, in get_host
    raise DisallowedHost(msg)
django.core.exceptions.DisallowedHost: Invalid HTTP_HOST header: '127.0.0.1:8000'. You may need to add '127.0.0.1' to ALLOWED_HOSTS.
Bad Request: /
Not Found: /
Not Found: /
Watching for file changes with StatReloader
/home/mz/Code/dashboard/django/dashboard/middleware.py changed, reloading.
Watching for file changes with StatReloader
/home/mz/Code/dashboard/django/dashboard/middleware.py changed, reloading.
Watching for file changes with StatReloader
Internal Server Error: /dashboard/api/auth/csrf/
Traceback (most recent call last):
  File "/home/mz/Code/dashboard/django/venv/lib/python3.11/site-packages/django/core/handlers/exception.py", line 55, in inner
    response = get_response(request)
               ^^^^^^^^^^^^^^^^^^^^^
  File "/home/mz/Code/dashboard/django/dashboard/middleware.py", line 61, in __call__
    log_request(request, response)
                ^^^^^^^
UnboundLocalError: cannot access local variable 'response' where it is not associated with a value
Internal Server Error: /dashboard/api/auth/csrf/
Traceback (most recent call last):
  File "/home/mz/Code/dashboard/django/venv/lib/python3.11/site-packages/django/core/handlers/exception.py", line 55, in inner
    response = get_response(request)
               ^^^^^^^^^^^^^^^^^^^^^
  File "/home/mz/Code/dashboard/django/dashboard/middleware.py", line 61, in __call__
    log_request(request, response)
                ^^^^^^^
UnboundLocalError: cannot access local variable 'response' where it is not associated with a value
Internal Server Error: /dashboard/api/auth/csrf/
Traceback (most recent call last):
  File "/home/mz/Code/dashboard/django/venv/lib/python3.11/site-packages/django/core/handlers/exception.py", line 55, in inner
    response = get_response(request)
               ^^^^^^^^^^^^^^^^^^^^^
  File "/home/mz/Code/dashboard/django/dashboard/middleware.py", line 61, in __call__
    log_request(request, response)
                ^^^^^^^
UnboundLocalError: cannot access local variable 'response' where it is not associated with a value
Internal Server Error: /dashboard/api/auth/csrf/
Traceback (most recent call last):
  File "/home/mz/Code/dashboard/django/venv/lib/python3.11/site-packages/django/core/handlers/exception.py", line 55, in inner
    response = get_response(request)
               ^^^^^^^^^^^^^^^^^^^^^
  File "/home/mz/Code/dashboard/django/dashboard/middleware.py", line 61, in __call__
    log_request(request, response)
                ^^^^^^^
UnboundLocalError: cannot access local variable 'response' where it is not associated with a value
Internal Server Error: /dashboard/api/auth/csrf/
Traceback (most recent call last):
  File "/home/mz/Code/dashboard/django/venv/lib/python3.11/site-packages/django/core/handlers/exception.py", line 55, in inner
    response = get_response(request)
               ^^^^^^^^^^^^^^^^^^^^^
  File "/home/mz/Code/dashboard/django/dashboard/middleware.py", line 61, in __call__
    log_request(request, response)
                ^^^^^^^
UnboundLocalError: cannot access local variable 'response' where it is not associated with a value
Internal Server Error: /dashboard/api/auth/csrf/
Traceback (most recent call last):
  File "/home/mz/Code/dashboard/django/venv/lib/python3.11/site-packages/django/core/handlers/exception.py", line 55, in inner
    response = get_response(request)
               ^^^^^^^^^^^^^^^^^^^^^
  File "/home/mz/Code/dashboard/django/dashboard/middleware.py", line 61, in __call__
    log_request(request, response)
                ^^^^^^^
UnboundLocalError: cannot access local variable 'response' where it is not associated with a value
Internal Server Error: /dashboard/api/auth/csrf/
Traceback (most recent call last):
  File "/home/mz/Code/dashboard/django/venv/lib/python3.11/site-packages/django/core/handlers/exception.py", line 55, in inner
    response = get_response(request)
               ^^^^^^^^^^^^^^^^^^^^^
  File "/home/mz/Code/dashboard/django/dashboard/middleware.py", line 61, in __call__
    log_request(request, response)
                ^^^^^^^
UnboundLocalError: cannot access local variable 'response' where it is not associated with a value
Internal Server Error: /dashboard/api/auth/csrf/
Traceback (most recent call last):
  File "/home/mz/Code/dashboard/django/venv/lib/python3.11/site-packages/django/core/handlers/exception.py", line 55, in inner
    response = get_response(request)
               ^^^^^^^^^^^^^^^^^^^^^
  File "/home/mz/Code/dashboard/django/dashboard/middleware.py", line 61, in __call__
    log_request(request, response)
                ^^^^^^^
UnboundLocalError: cannot access local variable 'response' where it is not associated with a value
Internal Server Error: /dashboard/api/auth/csrf/
Traceback (most recent call last):
  File "/home/mz/Code/dashboard/django/venv/lib/python3.11/site-packages/django/core/handlers/exception.py", line 55, in inner
    response = get_response(request)
               ^^^^^^^^^^^^^^^^^^^^^
  File "/home/mz/Code/dashboard/django/dashboard/middleware.py", line 61, in __call__
    log_request(request, response)
                ^^^^^^^
UnboundLocalError: cannot access local variable 'response' where it is not associated with a value
Internal Server Error: /dashboard/api/auth/csrf/
Traceback (most recent call last):
  File "/home/mz/Code/dashboard/django/venv/lib/python3.11/site-packages/django/core/handlers/exception.py", line 55, in inner
    response = get_response(request)
               ^^^^^^^^^^^^^^^^^^^^^
  File "/home/mz/Code/dashboard/django/dashboard/middleware.py", line 61, in __call__
    log_request(request, response)
                ^^^^^^^
UnboundLocalError: cannot access local variable 'response' where it is not associated with a value
/home/mz/Code/dashboard/django/dashboard/middleware.py changed, reloading.
Watching for file changes with StatReloader
/home/mz/Code/dashboard/django/dashboard/middleware.py changed, reloading.
Watching for file changes with StatReloader
/home/mz/Code/dashboard/django/dashboard/middleware.py changed, reloading.
Watching for file changes with StatReloader
Not Found: /dashboard/api
Not Found: /favicon.ico
Internal Server Error: /dashboard/api/database/Log/items/
Traceback (most recent call last):
  File "/home/mz/Code/dashboard/django/venv/lib/python3.11/site-packages/django/core/handlers/exception.py", line 55, in inner
    response = get_response(request)
               ^^^^^^^^^^^^^^^^^^^^^
  File "/home/mz/Code/dashboard/django/venv/lib/python3.11/site-packages/django/core/handlers/base.py", line 197, in _get_response
    response = wrapped_callback(request, *callback_args, **callback_kwargs)
               ^^^^^^^^^^^^^^^^^^^^^^^^^^^^^^^^^^^^^^^^^^^^^^^^^^^^^^^^^^^^
  File "/home/mz/Code/dashboard/django/dashboard/views/auth.py", line 35, in inner
    return fnc(*args, **kwargs)
           ^^^^^^^^^^^^^^^^^^^^
  File "/home/mz/Code/dashboard/django/dashboard/views/database.py", line 50, in select_items_view
    length = int(request.GET.get('length')) or -1
             ^^^^^^^^^^^^^^^^^^^^^^^^^^^^^^
TypeError: int() argument must be a string, a bytes-like object or a real number, not 'NoneType'
Internal Server Error: /dashboard/api/database/Log/items/
Traceback (most recent call last):
  File "/home/mz/Code/dashboard/django/venv/lib/python3.11/site-packages/django/core/handlers/exception.py", line 55, in inner
    response = get_response(request)
               ^^^^^^^^^^^^^^^^^^^^^
  File "/home/mz/Code/dashboard/django/venv/lib/python3.11/site-packages/django/core/handlers/base.py", line 197, in _get_response
    response = wrapped_callback(request, *callback_args, **callback_kwargs)
               ^^^^^^^^^^^^^^^^^^^^^^^^^^^^^^^^^^^^^^^^^^^^^^^^^^^^^^^^^^^^
  File "/home/mz/Code/dashboard/django/dashboard/views/auth.py", line 35, in inner
    return fnc(*args, **kwargs)
           ^^^^^^^^^^^^^^^^^^^^
  File "/home/mz/Code/dashboard/django/dashboard/views/database.py", line 50, in select_items_view
    length = int(request.GET.get('length')) or -1
             ^^^^^^^^^^^^^^^^^^^^^^^^^^^^^^
TypeError: int() argument must be a string, a bytes-like object or a real number, not 'NoneType'
Not Found: /
